Creating test database for alias 'default'...
Found 4 test(s).
System check identified no issues (0 silenced).
E...
======================================================================
ERROR: test_address_creation (users.tests.AddressModelTest.test_address_creation)
----------------------------------------------------------------------
Traceback (most recent call last):
  File "/opt/homebrew/lib/python3.11/site-packages/django/db/backends/utils.py", line 89, in _execute
    return self.cursor.execute(sql, params)
           ^^^^^^^^^^^^^^^^^^^^^^^^^^^^^^^^
psycopg2.errors.UndefinedColumn: column "country_id" of relation "users_address" does not exist
LINE 1: INSERT INTO "users_address" ("client_id", "country_id", "cit...
                                                  ^


The above exception was the direct cause of the following exception:

Traceback (most recent call last):
  File "/Users/db/dev/tuxTech/src/users/tests.py", line 93, in test_address_creation
    address = Address.objects.create(
              ^^^^^^^^^^^^^^^^^^^^^^^
  File "/opt/homebrew/lib/python3.11/site-packages/django/db/models/manager.py", line 85, in manager_method
    return getattr(self.get_queryset(), name)(*args, **kwargs)
           ^^^^^^^^^^^^^^^^^^^^^^^^^^^^^^^^^^^^^^^^^^^^^^^^^^^
  File "/opt/homebrew/lib/python3.11/site-packages/django/db/models/query.py", line 671, in create
    obj.save(force_insert=True, using=self.db)
  File "/opt/homebrew/lib/python3.11/site-packages/django/db/models/base.py", line 812, in save
    self.save_base(
  File "/opt/homebrew/lib/python3.11/site-packages/django/db/models/base.py", line 863, in save_base
    updated = self._save_table(
              ^^^^^^^^^^^^^^^^^
  File "/opt/homebrew/lib/python3.11/site-packages/django/db/models/base.py", line 1006, in _save_table
    results = self._do_insert(
              ^^^^^^^^^^^^^^^^
  File "/opt/homebrew/lib/python3.11/site-packages/django/db/models/base.py", line 1047, in _do_insert
    return manager._insert(
           ^^^^^^^^^^^^^^^^
  File "/opt/homebrew/lib/python3.11/site-packages/django/db/models/manager.py", line 85, in manager_method
    return getattr(self.get_queryset(), name)(*args, **kwargs)
           ^^^^^^^^^^^^^^^^^^^^^^^^^^^^^^^^^^^^^^^^^^^^^^^^^^^
  File "/opt/homebrew/lib/python3.11/site-packages/django/db/models/query.py", line 1791, in _insert
    return query.get_compiler(using=using).execute_sql(returning_fields)
           ^^^^^^^^^^^^^^^^^^^^^^^^^^^^^^^^^^^^^^^^^^^^^^^^^^^^^^^^^^^^^
  File "/opt/homebrew/lib/python3.11/site-packages/django/db/models/sql/compiler.py", line 1660, in execute_sql
    cursor.execute(sql, params)
  File "/opt/homebrew/lib/python3.11/site-packages/cacheops/transaction.py", line 98, in execute
    result = self._no_monkey.execute(self, sql, params)
             ^^^^^^^^^^^^^^^^^^^^^^^^^^^^^^^^^^^^^^^^^^
  File "/opt/homebrew/lib/python3.11/site-packages/django/db/backends/utils.py", line 67, in execute
    return self._execute_with_wrappers(
           ^^^^^^^^^^^^^^^^^^^^^^^^^^^^
  File "/opt/homebrew/lib/python3.11/site-packages/django/db/backends/utils.py", line 80, in _execute_with_wrappers
    return executor(sql, params, many, context)
           ^^^^^^^^^^^^^^^^^^^^^^^^^^^^^^^^^^^^
  File "/opt/homebrew/lib/python3.11/site-packages/django/db/backends/utils.py", line 84, in _execute
    with self.db.wrap_database_errors:
  File "/opt/homebrew/lib/python3.11/site-packages/django/db/utils.py", line 91, in __exit__
    raise dj_exc_value.with_traceback(traceback) from exc_value
  File "/opt/homebrew/lib/python3.11/site-packages/django/db/backends/utils.py", line 89, in _execute
    return self.cursor.execute(sql, params)
           ^^^^^^^^^^^^^^^^^^^^^^^^^^^^^^^^
django.db.utils.ProgrammingError: column "country_id" of relation "users_address" does not exist
LINE 1: INSERT INTO "users_address" ("client_id", "country_id", "cit...
                                                  ^


----------------------------------------------------------------------
Ran 4 tests in 0.155s

FAILED (errors=1)
Destroying test database for alias 'default'...
